Workbook

Sheet الملخص
A1: تقرير Tiket.com وBooking.com — سبتمبر 2026
A2: الأرقام بالروبية الإندونيسية. لا يشمل التقرير Traveloka. الأرقام الزرقاء مدخلة من التقرير الأول، والباقي صيغ تُحسب من الأوراق التفصيلية.
A4: 1) توزيع الإيراد بين الحسابين (إقامات سبتمبر)
A5: المنصة | B5: الحساب القديم (استنتاج) | C5: الحساب الجديد | D5: لم ينزل بعد | E5: الإجمالي | F5: ملاحظة
A6: Tiket.com | B6: =SUMIFS(Tiket_التحويلات!$C$5:$C$24,Tiket_التحويلات!$E$5:$E$24,"القديم (استنتاج)") -> 30384826 | C6: =SUMIFS(Tiket_التحويلات!$C$5:$C$24,Tiket_التحويلات!$E$5:$E$24,"الجديد (BNI)") -> 13290160 | D6: =E6-B6-C6 -> 2381266 | E6: 46056252 | F6: الجديد = تحويلات BNI بحسب التقرير. المتبقي: إقامات 30 سبتمبر (5 حجوزات)
A7: Booking.com | B7: =SUMIFS(Booking_الحجوزات!$L$5:$L$112,Booking_الحجوزات!$M$5:$M$112,"القديم (استنتاج)",Booking_الحجوزات!$E$5:$E$112,">="&DATE(2026,9,1)) -> 26327680 | C7: =SUMIFS(Booking_الحجوزات!$L$5:$L$112,Booking_الحجوزات!$M$5:$M$112,"الجديد (متوقع)") -> 13283018 | D7: =E7-B7-C7 -> 399982 | E7: 40010680 | F7: الجديد = دفعة 1 أكتوبر (متوقع، يلزمه كشف أكتوبر). المتبقي: حجز واحد من 30 سبتمبر
A8: الإجمالي | B8: =SUM(B6:B7) -> 56712506 | C8: =SUM(C6:C7) -> 26573178 | D8: =SUM(D6:D7) -> 2781248 | E8: =SUM(E6:E7) -> 86066932
A10: 2) Tiket.com — التفاصيل
A11: البند | B11: المبلغ | C11: عدد | F11: المصدر / ملاحظة
A12: إجمالي Tiket في التقرير | B12: =E6 -> 46056252 | F12: التقرير الأول، صف TIKET.COM (AM58)
A13: مجموع حجوزات issued في ملف Tiket | B13: =SUMIFS(Tiket_الحجوزات!$L$5:$L$131,Tiket_الحجوزات!$I$5:$I$131,"issued") -> 46056285 | C13: =COUNTIFS(Tiket_الحجوزات!$I$5:$I$131,"issued") -> 96 | F13: ملف Tiket
A14: الفرق (الملف − التقرير) | B14: =B13-B12 -> 33 | F14: تقريب أنصاف الروبية
A15: استرداد (refund) — لا يُحتسب إيرادًا | B15: =SUMIFS(Tiket_الحجوزات!$K$5:$K$131,Tiket_الحجوزات!$I$5:$I$131,"refund") -> 17847698 | C15: =COUNTIFS(Tiket_الحجوزات!$I$5:$I$131,"refund") -> 31 | F15: ردّ للضيوف؛ مستبعد من التقرير وهذا صحيح
A16: نزل في الحساب القديم (حسب التقرير) | B16: =B6 -> 30384826 | C16: =COUNTIFS(Tiket_التحويلات!$E$5:$E$24,"القديم (استنتاج)") -> 14 | F16: تحويلات 2–21 سبتمبر
A17: نزل في الحساب الجديد — حسب كشف BNI | B17: =Tiket_كشف_BNI!D32 -> 13290175 | C17: =COUNTA(Tiket_كشف_BNI!$E$5:$E$31) -> 27 | F17: تبدأ 22 سبتمبر
A18: نزل في الحساب الجديد — حسب التقرير | B18: =C6 -> 13290160 | C18: =COUNTIFS(Tiket_التحويلات!$E$5:$E$24,"الجديد (BNI)") -> 6 | F18: تحويلات 22–30 سبتمبر
A19: لم ينزل بعد (إقامات 30 سبتمبر) | B19: =D6 -> 2381266 | C19: =COUNTIFS(Tiket_الحجوزات!$P$5:$P$131,"لم ينزل بعد") -> 5 | F19: يُتوقع نزوله في أكتوبر
A21: 3) Booking.com — التفاصيل
A22: البند | B22: المبلغ | C22: عدد | F22: المصدر / ملاحظة
A23: إجمالي Booking في التقرير | B23: =E7 -> 40010680 | F23: التقرير الأول، صف BOOKING.COM (AM60)
A24: صافي إقامات سبتمبر في ملفات Booking | B24: =SUMIFS(Booking_الحجوزات!$L$5:$L$112,Booking_الحجوزات!$E$5:$E$112,">="&DATE(2026,9,1)) -> 39610698 | C24: =COUNTIFS(Booking_الحجوزات!$E$5:$E$112,">="&DATE(2026,9,1)) -> 86 | F24: دفعات 3 و10 و17 و24 سبتمبر و1 أكتوبر
A25: الفرق (التقرير − الملفات) = المتبقي بلا دفعة | B25: =B23-B24 -> 399982 | F25: حجز واحد من 30 سبتمبر لم يُدفع (التقرير قدّره 719,098)
A26: نزل في الحساب القديم — إقامات سبتمبر | B26: =SUMIFS(Booking_الحجوزات!$L$5:$L$112,Booking_الحجوزات!$M$5:$M$112,"القديم (استنتاج)",Booking_الحجوزات!$E$5:$E$112,">="&DATE(2026,9,1)) -> 26327680 | F26: دفعات 3–24 سبتمبر (الجزء الخاص بسبتمبر)
A27: نزل في الحساب القديم — إقامات أغسطس | B27: =SUMIFS(Booking_الحجوزات!$L$5:$L$112,Booking_الحجوزات!$M$5:$M$112,"القديم (استنتاج)",Booking_الحجوزات!$E$5:$E$112,"<"&DATE(2026,9,1)) -> 9655227 | F27: ضمن دفعة 3 سبتمبر؛ خارج تقرير سبتمبر
A28: إجمالي ما نزل في الحساب القديم فعليًا | B28: =B26+B27 -> 35982907 | C28: =COUNTIFS(Booking_الحجوزات!$M$5:$M$112,"القديم (استنتاج)") -> 85 | F28: يشمل 3 حجوزات ملغاة
A29: دفعة 1 أكتوبر (الحساب الجديد، متوقع) | B29: =SUMIFS(Booking_الحجوزات!$L$5:$L$112,Booking_الحجوزات!$M$5:$M$112,"الجديد (متوقع)") -> 13283018 | C29: =COUNTIFS(Booking_الحجوزات!$M$5:$M$112,"الجديد (متوقع)") -> 23 | F29: التقرير سجّل 12,963,879؛ الفرق = حجز Fadly Ahmad
A30: دفعة 1 أكتوبر حسب التقرير | B30: =Booking_الدفعات!F9 -> 12963879
A31: الفرق (الملف − التقرير) | B31: =B29-B30 -> 319139
A33: 4) تنبيهات وافتراضات
A34: • الحساب الجديد = BNI 2109686208 (ALMAGD TRADE)، وكشفه من 10 إلى 30 سبتمبر. كل مبلغ Tiket ورد فيه مؤكد برقم الحجز.
A35: • الحساب القديم: لا يتوفر كشفه. صُنّف عليه كل مبلغ من التقرير لم يظهر في كشف BNI (استنتاج وليس تأكيدًا).
A36: • Booking.com لم يحوّل شيئًا إلى كشف BNI في سبتمبر. دفعة 1 أكتوبر يُرجَّح نزولها في الحساب الجديد، ويلزم كشف أكتوبر لتأكيده.
A37: • لم أجد في كشف BNI مبلغًا أُوقف تحويله ثم حُوّل لاحقًا. دفعة Tiket بتاريخ 28 سبتمبر تغطي إقامات الجمعة إلى الأحد (إيقاع أسبوعي معتاد).
A38: • التقرير سجّل تحويل Tiket بتاريخ 29 سبتمبر (2,499,543) وهو وصل فعليًا في 30 سبتمبر، وسجّل دفعة Booking بتاريخ 17 سبتمبر في 19 سبتمبر.

Sheet Tiket_الحجوزات
A1: Tiket.com — كل الحجوزات (إقامات سبتمبر 2026)
A2: المصدر: ملف bookings_202610271002.xlsx من Tiket. عمودا «تاريخ النزول» و«مبلغ البنك» من كشف BNI (الحساب الجديد). الحساب القديم استنتاج بغياب كشفه.
A4: # | B4: رقم الحجز (Itinerary) | C4: اسم الضيف | D4: وقت الحجز | E4: الدخول | F4: الخروج | G4: الليالي | H4: نوع الغرفة | I4: الحالة | J4: سعر الغرفة | K4: مبلغ الاسترداد | L4: الإجمالي | M4: نوع الاسترداد | N4: تاريخ النزول (BNI) | O4: مبلغ البنك (BNI) | P4: الحساب
A5: 1 | B5: 77455031 | C5: Revina Refikasyah | D5: 46245.747 | E5: 46266 | F5: 46267 | G5: 1 | H5: Standard Tanpa Balkon - Room Only | I5: issued | J5: 311457.5 | K5: 0 | L5: 311457.5 | P5: القديم (استنتاج)
A6: 2 | B6: 77730201 | C6: Budiono Resah | D6: 46254.142 | E6: 46266 | F6: 46267 | G6: 1 | H6: Royal Deluxe with Mini Pool - Room Only | I6: refund | J6: 583490 | K6: 583490 | L6: 0 | M6: eRefund | P6: مسترجع
A7: 3 | B7: 78095630 | C7: Linda Linda | D7: 46266.43 | E7: 46266 | F7: 46267 | G7: 1 | H7: Royal Deluxe with Mini Pool - Room Only | I7: issued | J7: 583490 | K7: 0 | L7: 583490 | P7: القديم (استنتاج)
A8: 4 | B8: 78100749 | C8: Tito Kurnianto | D8: 46266.543 | E8: 46266 | F8: 46267 | G8: 1 | H8: Deluxe with Balcony - Room Only | I8: issued | J8: 390307.5 | K8: 0 | L8: 390307.5 | P8: القديم (استنتاج)
A9: 5 | B9: 78110655 | C9: Ardhana Halleza nova | D9: 46266.757 | E9: 46266 | F9: 46267 | G9: 1 | H9: Standard Dengan Balkon - Room Only | I9: issued | J9: 350882.5 | K9: 0 | L9: 350882.5 | P9: القديم (استنتاج)
A10: 6 | B10: 78120711 | C10: Anna Syahidah | D10: 46266.976 | E10: 46266 | F10: 46267 | G10: 1 | H10: Deluxe with Balcony - Room Only | I10: issued | J10: 390307.5 | K10: 0 | L10: 390307.5 | P10: القديم (استنتاج)
A11: 7 | B11: 77275602 | C11: kamin kamin | D11: 46240.618 | E11: 46267 | F11: 46268 | G11: 1 | H11: Royal Deluxe with Mini Pool - Room Only | I11: refund | J11: 583490 | K11: 583490 | L11: 0 | M11: eRefund | P11: مسترجع
A12: 8 | B12: 77275805 | C12: kamin kamin | D12: 46240.622 | E12: 46267 | F12: 46268 | G12: 1 | H12: Royal Deluxe with Mini Pool - Room Only | I12: refund | J12: 583490 | K12: 583490 | L12: 0 | M12: eRefund | P12: مسترجع
A13: 9 | B13: 78004393 | C13: Hasanudin Hasanudin | D13: 46262.967 | E13: 46267 | F13: 46268 | G13: 1 | H13: Deluxe with Balcony - Room Only | I13: refund | J13: 390307.5 | K13: 390307.5 | L13: 0 | M13: eRefund | P13: مسترجع
A14: 10 | B14: 78121255 | C14: Meilinda Amelia | D14: 46266.996 | E14: 46267 | F14: 46268 | G14: 1 | H14: Standard Tanpa Balkon - Room Only | I14: issued | J14: 311457.5 | K14: 0 | L14: 311457.5 | P14: القديم (استنتاج)
A15: 11 | B15: 78138963 | C15: Azka Alfariji | D15: 46267.646 | E15: 46267 | F15: 46268 | G15: 1 | H15: Deluxe with Balcony - Room Only | I15: issued | J15: 390307.5 | K15: 0 | L15: 390307.5 | P15: القديم (استنتاج)
A16: 12 | B16: 78144863 | C16: Trisaumi Syakira | D16: 46267.778 | E16: 46267 | F16: 46268 | G16: 1 | H16: Standard Dengan Balkon - Room Only | I16: issued | J16: 350882.5 | K16: 0 | L16: 350882.5 | P16: القديم (استنتاج)
A17: 13 | B17: 77538514 | C17: sarah selviani | D17: 46248.128 | E17: 46268 | F17: 46269 | G17: 1 | H17: Royal Deluxe with Mini Pool - Room Only | I17: refund | J17: 583490 | K17: 583490 | L17: 0 | M17: eRefund | P17: مسترجع
A18: 14 | B18: 78118871 | C18: Susnika merdiana | D18: 46266.929 | E18: 46268 | F18: 46269 | G18: 1 | H18: Royal Deluxe with Mini Pool - Room Only | I18: issued | J18: 583490 | K18: 0 | L18: 583490 | P18: القديم (استنتاج)
A19: 15 | B19: 78171271 | C19: Nazwalina Nazeera | D19: 46268.634 | E19: 46268 | F19: 46269 | G19: 1 | H19: Deluxe with Balcony - Room Only | I19: issued | J19: 390307.5 | K19: 0 | L19: 390307.5 | P19: القديم (استنتاج)
A20: 16 | B20: 78066836 | C20: Uum Umayah | D20: 46265.459 | E20: 46269 | F20: 46270 | G20: 1 | H20: Royal Deluxe with Mini Pool - Room Only | I20: refund | J20: 709650 | K20: 709650 | L20: 0 | M20: eRefund | P20: مسترجع
A21: 17 | B21: 78202579 | C21: Haddad Syarif | D21: 46269.578 | E21: 46269 | F21: 46270 | G21: 1 | H21: Deluxe with Balcony - Room Only | I21: issued | J21: 429732.5 | K21: 0 | L21: 429732.5 | P21: القديم (استنتاج)
A22: 18 | B22: 78202939 | C22: hanum mahriza | D22: 46269.586 | E22: 46269 | F22: 46270 | G22: 1 | H22: Deluxe with Balcony - Room Only | I22: issued | J22: 429732.5 | K22: 0 | L22: 429732.5 | P22: القديم (استنتاج)
A23: 19 | B23: 77710514 | C23: Ari Indraswati | D23: 46253.562 | E23: 46270 | F23: 46271 | G23: 1 | H23: Royal Deluxe with Mini Pool - Room Only | I23: issued | J23: 709650 | K23: 0 | L23: 709650 | P23: القديم (استنتاج)
A24: 20 | B24: 77927805 | C24: Junyasti duwi pramesti | D24: 46260.565 | E24: 46270 | F24: 46271 | G24: 1 | H24: Deluxe with Balcony - Room Only | I24: refund | J24: 429732.5 | K24: 429732.5 | L24: 0 | M24: eRefund | P24: مسترجع
A25: 21 | B25: 77927878 | C25: Junyasti duwi pramesti | D25: 46260.567 | E25: 46270 | F25: 46271 | G25: 1 | H25: Deluxe with Balcony - Room Only | I25: refund | J25: 429732.5 | K25: 429732.5 | L25: 0 | M25: eRefund | P25: مسترجع
A26: 22 | B26: 77931129 | C26: Dede april | D26: 46260.647 | E26: 46270 | F26: 46271 | G26: 1 | H26: Deluxe with Balcony - Room Only | I26: refund | J26: 429732.5 | K26: 429732.5 | L26: 0 | M26: eRefund | P26: مسترجع
A27: 23 | B27: 77931406 | C27: Dede april | D27: 46260.653 | E27: 46270 | F27: 46271 | G27: 1 | H27: Deluxe with Balcony - Room Only | I27: refund | J27: 429732.5 | K27: 429732.5 | L27: 0 | M27: eRefund | P27: مسترجع
A28: 24 | B28: 77931985 | C28: Dede april | D28: 46260.669 | E28: 46270 | F28: 46271 | G28: 1 | H28: Deluxe with Balcony - Room Only | I28: issued | J28: 429732.5 | K28: 0 | L28: 429732.5 | P28: القديم (استنتاج)
A29: 25 | B29: 78131304 | C29: abitah raynor | D29: 46267.483 | E29: 46270 | F29: 46271 | G29: 1 | H29: Standard Tanpa Balkon - Room Only | I29: issued | J29: 350882.5 | K29: 0 | L29: 350882.5 | P29: القديم (استنتاج)
A30: 26 | B30: 78134176 | C30: anggi anggi, mey mey | D30: 46267.543 | E30: 46270 | F30: 46271 | G30: 1 | H30: Standard Dengan Balkon - Room Only | I30: issued | J30: 780615 | K30: 0 | L30: 780615 | P30: القديم (استنتاج)
A31: 27 | B31: 78164590 | C31: zhalma syafitri alkobar | D31: 46268.488 | E31: 46270 | F31: 46271 | G31: 1 | H31: Deluxe with Balcony - Room Only | I31: issued | J31: 429732.5 | K31: 0 | L31: 429732.5 | P31: القديم (استنتاج)
A32: 28 | B32: 78181994 | C32: Bayu Rizky Gustiawan | D32: 46268.864 | E32: 46270 | F32: 46271 | G32: 1 | H32: Deluxe with Balcony - Room Only | I32: issued | J32: 429732.5 | K32: 0 | L32: 429732.5 | P32: القديم (استنتاج)
A33: 29 | B33: 78231815 | C33: Byan Afrizal Sardika | D33: 46270.461 | E33: 46270 | F33: 46271 | G33: 1 | H33: Superior With Minipool - Room Only | I33: issued | J33: 599260 | K33: 0 | L33: 599260 | P33: القديم (استنتاج)
A34: 30 | B34: 78236409 | C34: tasya desy s | D34: 46270.564 | E34: 46270 | F34: 46271 | G34: 1 | H34: Royal Deluxe with Mini Pool - Room Only | I34: issued | J34: 709650 | K34: 0 | L34: 709650 | P34: القديم (استنتاج)
A35: 31 | B35: 77888210 | C35: Buayu Lestari | D35: 46259.003 | E35: 46271 | F35: 46272 | G35: 1 | H35: Royal Deluxe with Mini Pool - Room Only | I35: refund | J35: 583490 | K35: 583490 | L35: 0 | M35: eRefund | P35: مسترجع
A36: 32 | B36: 78142469 | C36: hafiz ar | D36: 46267.724 | E36: 46271 | F36: 46272 | G36: 1 | H36: Royal Deluxe with Mini Pool - Room Only | I36: refund | J36: 583490 | K36: 583490 | L36: 0 | M36: eRefund | P36: مسترجع
A37: 33 | B37: 78146986 | C37: Ayu Lestari | D37: 46267.823 | E37: 46271 | F37: 46272 | G37: 1 | H37: Royal Deluxe with Mini Pool - Room Only | I37: issued | J37: 583490 | K37: 0 | L37: 583490 | P37: القديم (استنتاج)
A38: 34 | B38: 78241018 | C38: Haddad Syarif | D38: 46270.662 | E38: 46271 | F38: 46272 | G38: 1 | H38: Deluxe with Balcony - Room Only | I38: issued | J38: 390307.5 | K38: 0 | L38: 390307.5 | P38: القديم (استنتاج)
A39: 35 | B39: 78256308 | C39: DEDI Rianto | D39: 46271.209 | E39: 46271 | F39: 46272 | G39: 1 | H39: Standard Tanpa Balkon - Room Only | I39: issued | J39: 311457.5 | K39: 0 | L39: 311457.5 | P39: القديم (استنتاج)
A40: 36 | B40: 78260402 | C40: Agus budiarto | D40: 46271.434 | E40: 46271 | F40: 46272 | G40: 1 | H40: Superior With Minipool - Room Only | I40: issued | J40: 433675 | K40: 0 | L40: 433675 | P40: القديم (استنتاج)
A41: 37 | B41: 78276080 | C41: Antonius Kevin Wibowo | D41: 46271.869 | E41: 46271 | F41: 46272 | G41: 1 | H41: Deluxe with Balcony - Room Only | I41: issued | J41: 390307.5 | K41: 0 | L41: 390307.5 | P41: القديم (استنتاج)
...

Sheet Tiket_كشف_BNI
A1: Tiket.com — التحويلات التي نزلت في الحساب الجديد (BNI 2109686208)
A2: المصدر: كشف BNI من 10 إلى 30 سبتمبر 2026. كل تحويل Flip يحمل رقم حجز Tiket. فرق 0.5 روبية = تقريب.
A4: رقم القيد في الكشف | B4: تاريخ النزول | C4: الوقت | D4: المبلغ (البنك) | E4: رقم الحجز | F4: اسم الضيف | G4: تاريخ الدخول | H4: سعر Tiket | I4: الفرق | J4: يقابل تحويل التقرير بتاريخ
A5: 89 | B5: 46287 | C5: 18:10:26 | D5: 1166980 | E5: 78424771 | F5: adhi yoga sepriyanto | G5: 46285 | H5: =INDEX(Tiket_الحجوزات!$L$5:$L$131,MATCH(E5,Tiket_الحجوزات!$B$5:$B$131,0)) -> 1166980 | I5: =D5-H5 -> 0 | J5: 46287
A6: 94 | B6: 46288 | C6: 17:05:23 | D6: 390308 | E6: 78753800 | F6: NURLATIEF NURLATIEF | G6: 46287 | H6: =INDEX(Tiket_الحجوزات!$L$5:$L$131,MATCH(E6,Tiket_الحجوزات!$B$5:$B$131,0)) -> 390307.5 | I6: =D6-H6 -> 0.5 | J6: 46288
A7: 101 | B7: 46289 | C7: 17:12:08 | D7: 433675 | E7: 78775986 | F7: Nur khalifatun nisa | G7: 46288 | H7: =INDEX(Tiket_الحجوزات!$L$5:$L$131,MATCH(E7,Tiket_الحجوزات!$B$5:$B$131,0)) -> 433675 | I7: =D7-H7 -> 0 | J7: 46289
A8: 126 | B8: 46293 | C8: 18:05:51 | D8: 599260 | E8: 78780664 | F8: Yondra Fadillah | G8: 46291 | H8: =INDEX(Tiket_الحجوزات!$L$5:$L$131,MATCH(E8,Tiket_الحجوزات!$B$5:$B$131,0)) -> 599260 | I8: =D8-H8 -> 0 | J8: 46293
A9: 127 | B9: 46293 | C9: 18:05:51 | D9: 709650 | E9: 78849121 | F9: Mhd Bondan | G9: 46291 | H9: =INDEX(Tiket_الحجوزات!$L$5:$L$131,MATCH(E9,Tiket_الحجوزات!$B$5:$B$131,0)) -> 709650 | I9: =D9-H9 -> 0 | J9: 46293
A10: 128 | B10: 46293 | C10: 18:05:51 | D10: 429733 | E10: 78856206 | F10: Alifia Nabilah | G10: 46291 | H10: =INDEX(Tiket_الحجوزات!$L$5:$L$131,MATCH(E10,Tiket_الحجوزات!$B$5:$B$131,0)) -> 429732.5 | I10: =D10-H10 -> 0.5 | J10: 46293
A11: 129 | B11: 46293 | C11: 18:05:51 | D11: 390308 | E11: 78860444 | F11: Nurmala Sari | G11: 46291 | H11: =INDEX(Tiket_الحجوزات!$L$5:$L$131,MATCH(E11,Tiket_الحجوزات!$B$5:$B$131,0)) -> 390307.5 | I11: =D11-H11 -> 0.5 | J11: 46293
A12: 130 | B12: 46293 | C12: 18:05:51 | D12: 429733 | E12: 78838461 | F12: KIKI HANDAYANI | G12: 46290 | H12: =INDEX(Tiket_الحجوزات!$L$5:$L$131,MATCH(E12,Tiket_الحجوزات!$B$5:$B$131,0)) -> 429732.5 | I12: =D12-H12 -> 0.5 | J12: 46293
A13: 131 | B13: 46293 | C13: 18:05:51 | D13: 390308 | E13: 78799117 | F13: Nur Syabrina Lainun | G13: 46291 | H13: =INDEX(Tiket_الحجوزات!$L$5:$L$131,MATCH(E13,Tiket_الحجوزات!$B$5:$B$131,0)) -> 390307.5 | I13: =D13-H13 -> 0.5 | J13: 46293
A14: 132 | B14: 46293 | C14: 18:05:51 | D14: 390308 | E14: 78895837 | F14: Sis Kuswoyo | G14: 46292 | H14: =INDEX(Tiket_الحجوزات!$L$5:$L$131,MATCH(E14,Tiket_الحجوزات!$B$5:$B$131,0)) -> 390307.5 | I14: =D14-H14 -> 0.5 | J14: 46293
A15: 133 | B15: 46293 | C15: 18:05:51 | D15: 429733 | E15: 78475982 | F15: Mila Rosa Amelia | G15: 46291 | H15: =INDEX(Tiket_الحجوزات!$L$5:$L$131,MATCH(E15,Tiket_الحجوزات!$B$5:$B$131,0)) -> 429732.5 | I15: =D15-H15 -> 0.5 | J15: 46293
A16: 134 | B16: 46293 | C16: 18:05:51 | D16: 709650 | E16: 78799537 | F16: Siti indriyani | G16: 46291 | H16: =INDEX(Tiket_الحجوزات!$L$5:$L$131,MATCH(E16,Tiket_الحجوزات!$B$5:$B$131,0)) -> 709650 | I16: =D16-H16 -> 0 | J16: 46293
... A31: 163 | B31: 46295 | C31: 18:33:18 | D31: 433675 | E31: 78932755 | F31: i komang joni arta | G31: 46294 | H31: =INDEX(Tiket_الحجوزات!$L$5:$L$131,MATCH(E31,Tiket_الحجوزات!$B$5:$B$131,0)) -> 433675 | I31: =D31-H31 -> 0 | J31: 46295
A32: الإجمالي | D32: =SUM(D5:D31) -> 13290175 | H32: =SUM(H5:H31) -> 13290168 | I32: =SUM(I5:I31) -> 7.5

Sheet Tiket_التحويلات
A1: Tiket.com — التحويلات المسجّلة في التقرير الأول (20 تحويلًا)
A2: الأرقام الزرقاء مدخلة من التقرير (LAPORAN_NJD_SEPT_2026). «مبلغ البنك» يُحسب من كشف BNI للتحويلات التي دخلت الحساب الجديد.
A4: # | B4: تاريخ التحويل في التقرير | C4: المبلغ في التقرير | D4: ملاحظة التقرير | E4: الحساب | F4: تاريخ النزول في البنك | G4: مبلغ البنك (BNI) | H4: الفرق (البنك − التقرير)
A5: 1 | B5: 46267 | C5: 2026443 | D5: AISYAH | E5: القديم (استنتاج) | F5: —
A6: 2 | B6: 46268 | C6: 1052646 | D6: AISYAH | E6: القديم (استنتاج) | F6: —
A7: 3 | B7: 46269 | C7: 973797 | E7: القديم (استنتاج) | F7: —
A8: 4 | B8: 46272 | C8: 7407953 | E8: القديم (استنتاج) | F8: —
A9: 5 | B9: 46273 | C9: 3280158 | E9: القديم (استنتاج) | F9: —
A10: 6 | B10: 46274 | C10: 1403529 | E10: القديم (استنتاج) | F10: —
A11: 7 | B11: 46275 | C11: 583490 | E11: القديم (استنتاج) | F11: —
A12: 8 | B12: 46276 | C12: 934372 | E12: القديم (استنتاج) | F12: —
A13: 9 | B13: 46279 | C13: 7798259 | E13: القديم (استنتاج) | F13: —
A14: 10 | B14: 46280 | C14: 1407472 | E14: القديم (استنتاج) | F14: —
A15: 11 | B15: 46281 | C15: 823982 | E15: القديم (استنتاج) | F15: —
A16: 12 | B16: 46282 | C16: 390307 | E16: القديم (استنتاج) | F16: —
A17: 13 | B17: 46283 | C17: 583490 | E17: القديم (استنتاج) | F17: —
A18: 14 | B18: 46286 | C18: 1718928 | E18: القديم (استنتاج) | F18: —
A19: 15 | B19: 46287 | C19: 1166980 | E19: الجديد (BNI) | F19: 46287 | G19: =SUMIFS(Tiket_كشف_BNI!$D$5:$D$31,Tiket_كشف_BNI!$J$5:$J$31,B19) -> 1166980 | H19: =G19-C19 -> 0
A20: 16 | B20: 46288 | C20: 390307 | E20: الجديد (BNI) | F20: 46288 | G20: =SUMIFS(Tiket_كشف_BNI!$D$5:$D$31,Tiket_كشف_BNI!$J$5:$J$31,B20) -> 390308 | H20: =G20-C20 -> 1
A21: 17 | B21: 46289 | C21: 433675 | E21: الجديد (BNI) | F21: 46289 | G21: =SUMIFS(Tiket_كشف_BNI!$D$5:$D$31,Tiket_كشف_BNI!$J$5:$J$31,B21) -> 433675 | H21: =G21-C21 -> 0
A22: 18 | B22: 46293 | C22: 8365980 | E22: الجديد (BNI) | F22: 46293 | G22: =SUMIFS(Tiket_كشف_BNI!$D$5:$D$31,Tiket_كشف_BNI!$J$5:$J$31,B22) -> 8365990 | H22: =G22-C22 -> 10
A23: 19 | B23: 46294 | C23: 2499543 | E23: الجديد (BNI) | F23: 46295 | G23: =SUMIFS(Tiket_كشف_BNI!$D$5:$D$31,Tiket_كشف_BNI!$J$5:$J$31,B23) -> 2499547 | H23: =G23-C23 -> 4
A24: 20 | B24: 46295 | C24: 433675 | E24: الجديد (BNI) | F24: 46295 | G24: =SUMIFS(Tiket_كشف_BNI!$D$5:$D$31,Tiket_كشف_BNI!$J$5:$J$31,B24) -> 433675 | H24: =G24-C24 -> 0
A25: الإجمالي | C25: =SUM(C5:C24) -> 43674986 | G25: =SUM(G5:G24) -> 13290175 | H25: =SUM(H5:H24) -> 15
A27: ملاحظة: تحويل التقرير بتاريخ 29 سبتمبر (2,499,543) وصل فعليًا في البنك يوم 30 سبتمبر. الحساب القديم: لا يتوفر كشفه، فالتصنيف استنتاج (الدفعات قبل 22 سبتمبر غير موجودة في كشف BNI).

Sheet Booking_الحجوزات
A1: Booking.com — كل الحجوزات المدفوعة في الدفعات الخمس (3 و10 و17 و24 سبتمبر و1 أكتوبر)
A2: المصدر: ملفات الدفعات (CSV) من Booking.com. ملف دفعة 24 سبتمبر وصل مرتين بمحتوى مطابق وأُدخل مرة واحدة.
A4: تاريخ الدفعة | B4: رقم الدفعة | C4: رقم الحجز | D4: اسم الضيف | E4: الدخول | F4: الخروج | G4: الحالة | H4: المبلغ (إجمالي) | I4: العمولة | J4: ضريبة VAT | K4: رسوم الدفع | L4: الصافي | M4: الحساب
A5: 46268 | B5: Ssach3Ls8CQuvlhD | C5: 6385248831 | D5: Eko Wicaksono | E5: 46266 | F5: 46267 | G5: ok | H5: 495000 | I5: -74250 | J5: -9420 | K5: -11385 | L5: 399945 | M5: القديم (استنتاج)
A6: 46268 | B6: Ssach3Ls8CQuvlhD | C6: 6242738354 | D6: Muhammad Yoga armantia | E6: 46266 | F6: 46267 | G6: ok | H6: 395000 | I6: -59250 | J6: -7517 | K6: -9085 | L6: 319148 | M6: القديم (استنتاج)
A7: 46268 | B7: Ssach3Ls8CQuvlhD | C7: 5910274131 | D7: khai aryana | E7: 46266 | F7: 46267 | G7: ok | H7: 495000 | I7: -74250 | J7: -9420 | K7: -11385 | L7: 399945 | M7: القديم (استنتاج)
A8: 46268 | B8: Ssach3Ls8CQuvlhD | C8: 5775761592 | D8: Alif Nuur Faiiz | E8: 46266 | F8: 46267 | G8: ok | H8: 595000 | I8: -89250 | J8: -11323 | K8: -13685 | L8: 480742 | M8: القديم (استنتاج)
A9: 46268 | B9: Ssach3Ls8CQuvlhD | C9: 5635915886 | D9: Dinana Hanifah | E9: 46266 | F9: 46267 | G9: ok | H9: 495000 | I9: -74250 | J9: -9420 | K9: -11385 | L9: 399945 | M9: القديم (استنتاج)
A10: 46268 | B10: Ssach3Ls8CQuvlhD | C10: 6289059401 | D10: Adi Prinando | E10: 46265 | F10: 46266 | G10: ok | H10: 475000 | I10: -71250 | J10: -9040 | K10: -10925 | L10: 383785 | M10: القديم (استنتاج)
A11: 46268 | B11: Ssach3Ls8CQuvlhD | C11: 6604787607 | D11: Lutfi aldiar Ahmad | E11: 46264 | F11: 46265 | G11: ok | H11: 570000 | I11: -85500 | J11: -10847 | K11: -13110 | L11: 460543 | M11: القديم (استنتاج)
A12: 46268 | B12: Ssach3Ls8CQuvlhD | C12: 6465283637 | D12: Fajri Heryadi | E12: 46264 | F12: 46265 | G12: cancelled | H12: 375000 | I12: -56250 | J12: -7137 | K12: -8625 | L12: 302988 | M12: القديم (استنتاج)
A13: 46268 | B13: Ssach3Ls8CQuvlhD | C13: 5966438707 | D13: Sigit Agustian | E13: 46264 | F13: 46265 | G13: ok | H13: 475000 | I13: -71250 | J13: -9040 | K13: -10925 | L13: 383785 | M13: القديم (استنتاج)
A14: 46268 | B14: Ssach3Ls8CQuvlhD | C14: 5580011533 | D14: Dicky Rahmani Sutandi | E14: 46264 | F14: 46265 | G14: ok | H14: 475000 | I14: -71250 | J14: -9040 | K14: -10925 | L14: 383785 | M14: القديم (استنتاج)
A15: 46268 | B15: Ssach3Ls8CQuvlhD | C15: 5454361207 | D15: imam imam | E15: 46264 | F15: 46265 | G15: cancelled | H15: 375000 | I15: -56250 | J15: -7137 | K15: -8625 | L15: 302988 | M15: القديم (استنتاج)
A16: 46268 | B16: Ssach3Ls8CQuvlhD | C16: 5454347947 | D16: Eko Prastowo | E16: 46264 | F16: 46265 | G16: ok | H16: 475000 | I16: -71250 | J16: -9040 | K16: -10925 | L16: 383785 | M16: القديم (استنتاج)
... A112: 46296 | B112: q1dt4llKDuWcurng | C112: 6766075765 | D112: Evan Ahmed | E112: 46281 | F112: 46291 | G112: ok | H112: 5100000 | I112: -765000 | J112: -97053 | K112: -117300 | L112: 4120647 | M112: الجديد (متوقع)
A113: الإجمالي | H113: =SUM(H5:H112) -> 60975000 | I113: =SUM(I5:I112) -> -9146250 | J113: =SUM(J5:J112) -> -1160400 | K113: =SUM(K5:K112) -> -1402425 | L113: =SUM(L5:L112) -> 49265925

Sheet Booking_الدفعات
A1: Booking.com — الدفعات (Payouts)
A2: الصافي والعدد يُحسبان من ورقة «Booking_الحجوزات». المسجّل في التقرير مدخل من التقرير الأول (أرقام زرقاء).
A4: تاريخ الدفعة | B4: عدد الحجوزات | C4: صافي الدفعة (CSV) | D4: منها إقامات سبتمبر | E4: منها إقامات أغسطس | F4: المسجّل في التقرير | G4: الفرق (سبتمبر − التقرير) | H4: تاريخ التسجيل في التقرير | I4: الحساب | J4: ملاحظة
A5: 46268 | B5: =COUNTIFS(Booking_الحجوزات!$A$5:$A$112,A5) -> 27 | C5: =SUMIFS(Booking_الحجوزات!$L$5:$L$112,Booking_الحجوزات!$A$5:$A$112,A5) -> 11654952 | D5: =SUMIFS(Booking_الحجوزات!$L$5:$L$112,Booking_الحجوزات!$A$5:$A$112,A5,Booking_الحجوزات!$E$5:$E$112,">="&DATE(2026,9,1)) -> 1999725 | E5: =C5-D5 -> 9655227 | F5: 1999726 | G5: =D5-F5 -> -1 | H5: 46266 | I5: القديم (استنتاج) | J5: الجزء الأكبر (إقامات أغسطس) لا يدخل تقرير سبتمبر؛ فيه 3 حجوزات ملغاة
A6: 46275 | B6: =COUNTIFS(Booking_الحجوزات!$A$5:$A$112,A6) -> 21 | C6: =SUMIFS(Booking_الحجوزات!$L$5:$L$112,Booking_الحجوزات!$A$5:$A$112,A6) -> 8924022 | D6: =SUMIFS(Booking_الحجوزات!$L$5:$L$112,Booking_الحجوزات!$A$5:$A$112,A6,Booking_الحجوزات!$E$5:$E$112,">="&DATE(2026,9,1)) -> 8924022 | E6: =C6-D6 -> 0 | F6: 8924029 | G6: =D6-F6 -> -7 | H6: 46275 | I6: القديم (استنتاج)
A7: 46282 | B7: =COUNTIFS(Booking_الحجوزات!$A$5:$A$112,A7) -> 23 | C7: =SUMIFS(Booking_الحجوزات!$L$5:$L$112,Booking_الحجوزات!$A$5:$A$112,A7) -> 9562316 | D7: =SUMIFS(Booking_الحجوزات!$L$5:$L$112,Booking_الحجوزات!$A$5:$A$112,A7,Booking_الحجوزات!$E$5:$E$112,">="&DATE(2026,9,1)) -> 9562316 | E7: =C7-D7 -> 0 | F7: 9562325 | G7: =D7-F7 -> -9 | H7: 46284 | I7: القديم (استنتاج) | J7: سُجّلت في التقرير بتاريخ 19 سبتمبر
A8: 46289 | B8: =COUNTIFS(Booking_الحجوزات!$A$5:$A$112,A8) -> 14 | C8: =SUMIFS(Booking_الحجوزات!$L$5:$L$112,Booking_الحجوزات!$A$5:$A$112,A8) -> 5841617 | D8: =SUMIFS(Booking_الحجوزات!$L$5:$L$112,Booking_الحجوزات!$A$5:$A$112,A8,Booking_الحجوزات!$E$5:$E$112,">="&DATE(2026,9,1)) -> 5841617 | E8: =C8-D8 -> 0 | F8: 5841623 | G8: =D8-F8 -> -6 | H8: 46289 | I8: القديم (استنتاج)
A9: 46296 | B9: =COUNTIFS(Booking_الحجوزات!$A$5:$A$112,A9) -> 23 | C9: =SUMIFS(Booking_الحجوزات!$L$5:$L$112,Booking_الحجوزات!$A$5:$A$112,A9) -> 13283018 | D9: =SUMIFS(Booking_الحجوزات!$L$5:$L$112,Booking_الحجوزات!$A$5:$A$112,A9,Booking_الحجوزات!$E$5:$E$112,">="&DATE(2026,9,1)) -> 13283018 | E9: =C9-D9 -> 0 | F9: 12963879 | G9: =D9-F9 -> 319139 | H9: 46296 | I9: الجديد (متوقع) | J9: التقرير لم يشمل حجز Fadly Ahmad (319,148). يشمل حجز Evan Ahmed (10 ليالٍ، 4,120,647). التأكد من نزوله يلزمه كشف أكتوبر
A10: الإجمالي | B10: =SUM(B5:B9) -> 108 | C10: =SUM(C5:C9) -> 49265925 | D10: =SUM(D5:D9) -> 39610698 | E10: =SUM(E5:E9) -> 9655227 | F10: =SUM(F5:F9) -> 39291582 | G10: =SUM(G5:G9) -> 319116
A12: الفروق الصغيرة (6–9 روبية) سببها تقريب الأجزاء في Booking. الفرق الأكبر في دفعة 1 أكتوبر سببه حجز Fadly Ahmad (يظهر في الدفعة بالـ CSV ولم يُحتسب في تحويل التقرير).

Sheet مقارنة_يومية
A1: مقارنة يومية بحسب تاريخ الدخول: التقرير الأول مقابل ملفات المنصتين
A2: التقرير: صفّا TIKET.COM وBOOKING.COM لكل يوم. الأيام التي يختلف فيها التوزيع (دون اختلاف الإجمالي) مظلّلة. إقامة Evan Ahmed (Booking، 10 ليالٍ من 16 إلى 26 سبتمبر) تظهر كلها يوم 16 في الملف، بينما يوزّعها التقرير على الأيام 16–25.
A4: التاريخ | B4: Tiket: التقرير | C4: Tiket: الملف (issued) | D4: فرق Tiket | E4: Booking: التقرير | F4: Booking: الملفات (الصافي) | G4: فرق Booking
A5: 46266 | B5: 2026443 | C5: =SUMIFS(Tiket_الحجوزات!$L$5:$L$131,Tiket_الحجوزات!$E$5:$E$131,A5,Tiket_الحجوزات!$I$5:$I$131,"issued") -> 2026445 | D5: =C5-B5 -> 2 | E5: 1999725 | F5: =SUMIFS(Booking_الحجوزات!$L$5:$L$112,Booking_الحجوزات!$E$5:$E$112,A5) -> 1999725 | G5: =F5-E5 -> 0
A6: 46267 | B6: 1052646 | C6: =SUMIFS(Tiket_الحجوزات!$L$5:$L$131,Tiket_الحجوزات!$E$5:$E$131,A6,Tiket_الحجوزات!$I$5:$I$131,"issued") -> 1052647.5 | D6: =C6-B6 -> 1.5 | E6: 480742 | F6: =SUMIFS(Booking_الحجوزات!$L$5:$L$112,Booking_الحجوزات!$E$5:$E$112,A6) -> 480742 | G6: =F6-E6 -> 0
A7: 46268 | B7: 973797 | C7: =SUMIFS(Tiket_الحجوزات!$L$5:$L$131,Tiket_الحجوزات!$E$5:$E$131,A7,Tiket_الحجوزات!$I$5:$I$131,"issued") -> 973797.5 | D7: =C7-B7 -> 0.5 | E7: 799890 | F7: =SUMIFS(Booking_الحجوزات!$L$5:$L$112,Booking_الحجوزات!$E$5:$E$112,A7) -> 799890 | G7: =F7-E7 -> 0
A8: 46269 | B8: 859464 | C8: =SUMIFS(Tiket_الحجوزات!$L$5:$L$131,Tiket_الحجوزات!$E$5:$E$131,A8,Tiket_الحجوزات!$I$5:$I$131,"issued") -> 859465 | D8: =C8-B8 -> 1 | E8: 359547 | F8: =SUMIFS(Booking_الحجوزات!$L$5:$L$112,Booking_الحجوزات!$E$5:$E$112,A8) -> 359546 | G8: =F8-E8 -> -1
A9: 46270 | B9: 4439252 | C9: =SUMIFS(Tiket_الحجوزات!$L$5:$L$131,Tiket_الحجوزات!$E$5:$E$131,A9,Tiket_الحجوزات!$I$5:$I$131,"issued") -> 4439255 | D9: =C9-B9 -> 3 | E9: 2722861 | F9: =SUMIFS(Booking_الحجوزات!$L$5:$L$112,Booking_الحجوزات!$E$5:$E$112,A9) -> 2722855 | G9: =F9-E9 -> -6
A10: 46271 | B10: 2499543 | C10: =SUMIFS(Tiket_الحجوزات!$L$5:$L$131,Tiket_الحجوزات!$E$5:$E$131,A10,Tiket_الحجوزات!$I$5:$I$131,"issued") -> 2889852.5 | D10: =C10-B10 -> 390309.5 | E10: 1280632 | F10: =SUMIFS(Booking_الحجوزات!$L$5:$L$112,Booking_الحجوزات!$E$5:$E$112,A10) -> 1280632 | G10: =F10-E10 -> 0
A11: 46272 | B11: 3201307 | C11: =SUMIFS(Tiket_الحجوزات!$L$5:$L$131,Tiket_الحجوزات!$E$5:$E$131,A11,Tiket_الحجوزات!$I$5:$I$131,"issued") -> 3122460 | D11: =C11-B11 -> -78847 | E11: 2161319 | F11: =SUMIFS(Booking_الحجوزات!$L$5:$L$112,Booking_الحجوزات!$E$5:$E$112,A11) -> 2161319 | G11: =F11-E11 -> 0
A12: 46273 | B12: 1092071 | C12: =SUMIFS(Tiket_الحجوزات!$L$5:$L$131,Tiket_الحجوزات!$E$5:$E$131,A12,Tiket_الحجوزات!$I$5:$I$131,"issued") -> 780615 | D12: =C12-B12 -> -311456 | E12: 1119038 | F12: =SUMIFS(Booking_الحجوزات!$L$5:$L$112,Booking_الحجوزات!$E$5:$E$112,A12) -> 1119038 | G12: =F12-E12 -> 0
A13: 46274 | B13: 583490 | C13: =SUMIFS(Tiket_الحجوزات!$L$5:$L$131,Tiket_الحجوزات!$E$5:$E$131,A13,Tiket_الحجوزات!$I$5:$I$131,"issued") -> 583490 | D13: =C13-B13 -> 0 | E13: 1119038 | F13: =SUMIFS(Booking_الحجوزات!$L$5:$L$112,Booking_الحجوزات!$E$5:$E$112,A13) -> 1119038 | G13: =F13-E13 -> 0
A14: 46275 | B14: 934372 | C14: =SUMIFS(Tiket_الحجوزات!$L$5:$L$131,Tiket_الحجوزات!$E$5:$E$131,A14,Tiket_الحجوزات!$I$5:$I$131,"issued") -> 934372.5 | D14: =C14-B14 -> 0.5 | E14: 319148 | F14: =SUMIFS(Booking_الحجوزات!$L$5:$L$112,Booking_الحجوزات!$E$5:$E$112,A14) -> 319148 | G14: =F14-E14 -> 0
A15: 46276 | B15: 2270878 | C15: =SUMIFS(Tiket_الحجوزات!$L$5:$L$131,Tiket_الحجوزات!$E$5:$E$131,A15,Tiket_الحجوزات!$I$5:$I$131,"issued") -> 2980530 | D15: =C15-B15 -> 709652 | E15: 2201720 | F15: =SUMIFS(Booking_الحجوزات!$L$5:$L$112,Booking_الحجوزات!$E$5:$E$112,A15) -> 2201715 | G15: =F15-E15 -> -5
A16: 46277 | B16: 3729602 | C16: =SUMIFS(Tiket_الحجوزات!$L$5:$L$131,Tiket_الحجوزات!$E$5:$E$131,A16,Tiket_الحجوزات!$I$5:$I$131,"issued") -> 3019955 | D16: =C16-B16 -> -709647 | E16: 2722861 | F16: =SUMIFS(Booking_الحجوزات!$L$5:$L$112,Booking_الحجوزات!$E$5:$E$112,A16) -> 2722855 | G16: =F16-E16 -> -6
... A34: 46295 | B34: 2381269 | C34: =SUMIFS(Tiket_الحجوزات!$L$5:$L$131,Tiket_الحجوزات!$E$5:$E$131,A34,Tiket_الحجوزات!$I$5:$I$131,"issued") -> 2381270 | D34: =C34-B34 -> 1 | E34: 719093 | F34: =SUMIFS(Booking_الحجوزات!$L$5:$L$112,Booking_الحجوزات!$E$5:$E$112,A34) -> 319148 | G34: =F34-E34 -> -399945
A35: الإجمالي | B35: =SUM(B5:B34) -> 46056252 | C35: =SUM(C5:C34) -> 46056285 | D35: =SUM(D5:D34) -> 33 | E35: =SUM(E5:E34) -> 40010680 | F35: =SUM(F5:F34) -> 39610698 | G35: =SUM(G5:G34) -> -399982
A37: ملاحظة: إجمالي Booking في الملفات أقل من التقرير بنحو 399,982 (حجز من 30 سبتمبر لم يُدفع بعد). إجمالي Tiket يتطابق بفرق تقريب 33 روبية.
